<?xml version="1.0" encoding="utf-8"?>
<!-- =================================================================================== -->
<!-- |    This document was autogenerated by xacro from fanuc_m710.xacro               | -->
<!-- |    EDITING THIS FILE BY HAND IS NOT RECOMMENDED                                 | -->
<!-- =================================================================================== -->
<!-- This URDF was automatically created by SolidWorks to URDF Exporter! Originally created by Stephen Brawner (brawner@gmail.com) 
     Commit Version: 1.5.1-0-g916b5db  Build Version: 1.5.7152.31018
     For more information, please see http://wiki.ros.org/sw_urdf_exporter -->
<robot name="fanuc_m710" xmlns:tesseract="http://tesseract.ros.org" tesseract:make_convex="true">
  <link name="world"/>
  <!-- <link name="base"/> -->
  <link name="flange"/>
  <link name="tool0"/>
  <link name="y_prismatic"/>
  <link name="base_link">
    <inertial>
      <origin rpy="0 0 0" xyz="-0.0457626848128747 -0.00308618625573551 0.105717230207467"/>
      <mass value="359.91"/>
      <inertia ixx="8.31" ixy="0.01" ixz="0.26" iyy="9.17" iyz="-0.01" izz="14.11"/>
    </inertial>
    <visual>
      <origin rpy="0 0 0" xyz="0 0 0"/>
      <geometry>
        <mesh filename="/workspaces/trajopt-playground/config/robots/fanuc_m710/meshes/visual/base_link.dae"/>
      </geometry>
      <material name="">
        <color rgba="0.027450980392156862 0.050980392156862744 0.050980392156862744 1.0"/>
      </material>
    </visual>
    <collision>
      <origin rpy="0 0 0" xyz="0 0 0"/>
      <geometry>
        <mesh filename="/workspaces/trajopt-playground/config/robots/fanuc_m710/meshes/collision/base_link.STL"/>
      </geometry>
    </collision>
  </link>
  <link name="link_1">
    <inertial>
      <origin rpy="0 0 0" xyz="0.0537244171222486 -0.00788087446529528 -0.103391553237361"/>
      <mass value="308.28"/>
      <inertia ixx="10.23" ixy="0.19" ixz="1.86" iyy="8.66" iyz="-0.26" izz="10.13"/>
    </inertial>
    <visual>
      <origin rpy="0 0 0" xyz="0 0 0"/>
      <geometry>
        <mesh filename="/workspaces/trajopt-playground/config/robots/fanuc_m710/meshes/visual/L1.dae"/>
      </geometry>
      <material name="">
        <color rgba="0.792156862745098 0.819607843137255 0.933333333333333 1"/>
      </material>
    </visual>
    <collision>
      <origin rpy="0 0 0" xyz="0 0 0"/>
      <geometry>
        <mesh filename="/workspaces/trajopt-playground/config/robots/fanuc_m710/meshes/collision/L1.STL"/>
      </geometry>
    </collision>
  </link>
  <link name="link_2">
    <inertial>
      <origin rpy="0 0 0" xyz="0.000815799778495191 -0.535445214768339 0.176361083123118"/>
      <mass value="210.12"/>
      <inertia ixx="32.27" ixy="0.06" ixz="-0.02" iyy="1.05" iyz="-0.75" izz="32.68"/>
    </inertial>
    <visual>
      <origin rpy="0 0 0" xyz="0 0 0"/>
      <geometry>
        <mesh filename="/workspaces/trajopt-playground/config/robots/fanuc_m710/meshes/visual/L2.dae"/>
      </geometry>
      <material name="">
        <color rgba="1 1 0 1"/>
      </material>
    </visual>
    <collision>
      <origin rpy="0 0 0" xyz="0 0 0"/>
      <geometry>
        <mesh filename="/workspaces/trajopt-playground/config/robots/fanuc_m710/meshes/collision/L2.STL"/>
      </geometry>
    </collision>
  </link>
  <link name="link_3">
    <inertial>
      <origin rpy="0 0 0" xyz="0.0832895738601431 -0.000799323950832126 0.0322494414518494"/>
      <mass value="260.86"/>
      <inertia ixx="4.86" ixy="-0.68" ixz="-0.37" iyy="4.84" iyz="0.56" izz="5.67"/>
    </inertial>
    <visual>
      <origin rpy="0 0 0" xyz="0 0 0"/>
      <geometry>
        <mesh filename="/workspaces/trajopt-playground/config/robots/fanuc_m710/meshes/visual/L3.dae"/>
      </geometry>
      <material name="">
        <color rgba="0.792156862745098 0.819607843137255 0.933333333333333 1"/>
      </material>
    </visual>
    <collision>
      <origin rpy="0 0 0" xyz="0 0 0"/>
      <geometry>
        <mesh filename="/workspaces/trajopt-playground/config/robots/fanuc_m710/meshes/collision/L3.STL"/>
      </geometry>
    </collision>
  </link>
  <link name="link_4">
    <inertial>
      <origin rpy="0 0 0" xyz="-7.92843802921439E-05 0.00761594170371452 -0.778015329725021"/>
      <mass value="94.32"/>
      <inertia ixx="10.64" ixy="0.0" ixz="0.0" iyy="10.6" iyz="-0.37" izz="0.23"/>
    </inertial>
    <visual>
      <origin rpy="0 0 0" xyz="0 0 0"/>
      <geometry>
        <mesh filename="/workspaces/trajopt-playground/config/robots/fanuc_m710/meshes/visual/L4.dae"/>
      </geometry>
      <material name="">
        <color rgba="0.792156862745098 0.819607843137255 0.933333333333333 1"/>
      </material>
    </visual>
    <collision>
      <origin rpy="0 0 0" xyz="0 0 0"/>
      <geometry>
        <mesh filename="/workspaces/trajopt-playground/config/robots/fanuc_m710/meshes/collision/L4.STL"/>
      </geometry>
    </collision>
  </link>
  <link name="link_5">
    <inertial>
      <origin rpy="0 0 0" xyz="1.73516030432808E-08 -0.0745609600170947 -0.0181683741455079"/>
      <mass value="14.01"/>
      <inertia ixx="0.08" ixy="0.0" ixz="0.0" iyy="0.05" iyz="-0.01" izz="0.06"/>
    </inertial>
    <visual>
      <origin rpy="0 0 0" xyz="0 0 0"/>
      <geometry>
        <mesh filename="/workspaces/trajopt-playground/config/robots/fanuc_m710/meshes/visual/L5.dae"/>
      </geometry>
      <material name="">
        <color rgba="0.792156862745098 0.819607843137255 0.933333333333333 1"/>
      </material>
    </visual>
    <collision>
      <origin rpy="0 0 0" xyz="0 0 0"/>
      <geometry>
        <mesh filename="/workspaces/trajopt-playground/config/robots/fanuc_m710/meshes/collision/L5.STL"/>
      </geometry>
    </collision>
  </link>
  <link name="link_6">
    <inertial>
      <origin rpy="0 0 0" xyz="0 1.32610240587262E-15 0.0108946161466064"/>
      <mass value="1.61"/>
      <inertia ixx="0" ixy="0.0" ixz="0.0" iyy="0.0" iyz="0.0" izz="0.0"/>
    </inertial>
    <visual>
      <origin rpy="0 0 0" xyz="0 0 0"/>
      <geometry>
        <mesh filename="/workspaces/trajopt-playground/config/robots/fanuc_m710/meshes/visual/L6.dae"/>
      </geometry>
      <material name="">
        <color rgba="0.792156862745098 0.819607843137255 0.933333333333333 1"/>
      </material>
    </visual>
    <collision>
      <origin rpy="0 0 0" xyz="0 0 0"/>
      <geometry>
        <mesh filename="/workspaces/trajopt-playground/config/robots/fanuc_m710/meshes/collision/L6.STL"/>
      </geometry>
    </collision>
  </link>
  <!-- <joint name="world_joint" type="fixed">
    <parent link="world"/>
    <child link="base_link"/>
    <origin rpy="-0 0 0" xyz="0.0 0.0 0.0"/>
  </joint> -->
  <joint name="world_joint" type="fixed">
    <parent link="world"/>
    <child link="y_prismatic"/>
    <origin rpy="-0 0 0" xyz="0.0 0.0 0.0"/>
  </joint>
  <joint name="extender_joint" type="prismatic">
    <parent link="y_prismatic"/>
    <child link="base_link"/>
    <origin rpy="0 0 0" xyz="0.0 0.0 0.0"/>
    <axis xyz="0 1 0"/>
    <limit effort="0" lower="0" upper="6" velocity="0.3"/>
  </joint>
  <!-- <joint name="base_link_base" type="fixed">
    <origin rpy="0 0 0" xyz="0 0 0.1277"/>
    <parent link="base_link"/>
    <child link="base"/>
  </joint> -->
  <!-- <joint name="world_joint" type="fixed">
    <parent link="world"/>
    <child link="base_link"/>
    <origin rpy="-0 0 0" xyz="0.0 0.0 0.0"/>
  </joint> -->
  <!-- <joint name="base_link_base" type="fixed">
    <origin rpy="0 0 1.5707" xyz="0 0 0"/>
    <parent link="base"/>
    <child link="base_link"/>
  </joint> -->
  <joint name="joint_1" type="revolute">
    <origin rpy="0 0 0" xyz="0 0 0.565"/>
    <parent link="base_link"/>
    <child link="link_1"/>
    <axis xyz="0 0 1"/>
    <limit effort="0" lower="-3.141592653589793" upper="3.141592653589793" velocity="3.05"/>
  </joint>
  <joint name="joint_2" type="revolute">
    <origin rpy="-1.5708 0 0" xyz="0.15 0 0"/>
    <parent link="link_1"/>
    <child link="link_2"/>
    <axis xyz="0 0 1"/>
    <limit effort="0" lower="-1.5707963267948966" upper="2.356194490192345" velocity="3.05"/>
  </joint>
  <joint name="joint_3" type="revolute">
    <origin rpy="-3.1416 0 -1.5708" xyz="0 -1.15 0"/>
    <parent link="link_2"/>
    <child link="link_3"/>
    <axis xyz="0 0 1"/>
    <limit effort="0" lower="-1.5707963267948966" upper="4.886921905584122" velocity="3.05"/>
  </joint>
  <joint name="joint_4" type="revolute">
    <origin rpy="1.5708 0 -3.1416" xyz="0.17 0 0"/>
    <parent link="link_3"/>
    <child link="link_4"/>
    <axis xyz="0 0 1"/>
    <limit effort="0" lower="-6.283185307179586" upper="6.283185307179586" velocity="4.36"/>
  </joint>
  <joint name="joint_5" type="revolute">
    <origin rpy="1.5708 0 -3.1416" xyz="0 0 -1.295"/>
    <parent link="link_4"/>
    <child link="link_5"/>
    <axis xyz="0 0 1"/>
    <limit effort="0" lower="-2.181661564992912" upper="2.181661564992912" velocity="4.36"/>
  </joint>
  <joint name="joint_6" type="revolute">
    <origin rpy="-1.5708 0 0" xyz="0 -0.175 0"/>
    <parent link="link_5"/>
    <child link="link_6"/>
    <axis xyz="0 0 1"/>
    <limit effort="0" lower="-6.283185307179586" upper="6.283185307179586" velocity="6.19"/>
  </joint>
  <joint name="joint_6_flange" type="fixed">
    <origin rpy="0 0 0" xyz="0 0 0"/>
    <parent link="link_6"/>
    <child link="flange"/>
  </joint>
  <joint name="link_6_tool0" type="fixed">
    <origin rpy="3.1415 0 0" xyz="0 0 0"/>
    <parent link="link_6"/>
    <child link="tool0"/>
  </joint>
</robot>
